Workbook
Name den: SHEET1!$C$1:$C$27
Name GRADE: [1]SHEET1!$A$1:$A$27
Name GRADE: SHEET1!$A$1:$A$27
Name MATERIAL: [1]SHEET1!$H$6:$H$8
Name MATERIAL: SHEET1!$H$6:$H$8

Sheet COST-SUMMARY
A1: COST SUMMARY FOR -TOOL NO: BM454 Veedol 600ml M01 08Cavity SEB Mold SEB101 FN
A2: S.NO | B2: Description | C2: Amount - Rs
A3: 1 | B3: Cost of Inserts | C3: ='Mold and Mask Parts'!V22 -> 542517.72
A4: 2 | B4: Cost of Mask Parts | C4: ='Mold and Mask Parts'!V39 -> 87964.053
A5: 3 | B5: Cost of Mold Base parts | C5: ='Mold Base Parts '!V19 -> 19971.084
A6: 4 | B6: Cost of Standard parts | C6: ='Standard Parts '!L47 -> 57629
A7: 5 | B7: Cost of Fastners | C7: =Fastners!L34 -> 9668
A8: 6 | B8: Cost of Electrodes | C8: =Elec!Z15 -> 14874.42
B9: Total Amount :- | C9: =SUM(C3:C8) -> 732624.28

Sheet Mold and Mask Parts
A1: PRATHIRAJ METAL MASTERS PVT.LTD
A2: PART LIST (Finishing Sizes on 14-02-26)
A3: TOOL NO : BM454 Veedol 600ml M01 08Cavity SEB Mold SEB101 FN
A4: ITEM:- INSERTS/MAIN PARTS
A5: S.NO | B5: DESCRIPTION | C5: MATERIAL | D5: GRADE | E5: QTY | H5: FINISHED SIZES | M5: HB/HRC | N5: REMARKS | O5: Length/Dia | P5: Height | Q5: Width | R5: Qty | S5: Weight | T5: Total Weight | U5: Rate | V5: Amount
A6: 1 | B6: BODY INSERT- B & P | C6: ALUMINIUM | D6: HOKOTOL/ALUMOLD1-500 | E6: 2 | H6: 1230 | I6: x | J6: 126 | K6: x | L6: 246.454 | M6: HB-180 | O6: =H6+5 -> 1235 | P6: =J6+5 -> 131 | Q6: =L6+5 -> 251.454 | R6: =E6+G6 -> 2 | S6: =SUM(O6*P6*Q6)*W6/1000000 -> 122.04446 | T6: =SUM(R6*S6) -> 244.08891 | U6: 1200 | V6: =SUM(T6*U6) -> 292906.69 | W6: 3 | AH6: 246.7
A7: 2 | B7: BASE INSERT- B & P | C7: STEEL | D7: 1,2085 | E7: 2 | H7: 1230 | I7: x | J7: 101 | K7: x | L7: 55.6 | O7: =H7+5 -> 1235 | P7: =J7+5 -> 106 | Q7: =L7+5 -> 60.6 | R7: =E7+G7 -> 2 | S7: =SUM(O7*P7*Q7)*W7/1000000 -> 63.861825 | T7: =SUM(R7*S7) -> 127.72365 | U7: 400 | V7: =SUM(T7*U7) -> 51089.46 | W7: 8.05 | AH7: 55.5
A8: 3 | B8: BOTTOM INSERT- B & P | C8: ALUMINIUM | D8: HOKOTOL/ALUMOLD1-500 | E8: 2 | H8: 1230 | I8: x | J8: 126 | K8: x | L8: 115 | M8: HB-180 | O8: =H8+5 -> 1235 | P8: =J8+5 -> 131 | Q8: =L8+5 -> 120 | R8: =E8+G8 -> 2 | S8: =SUM(O8*P8*Q8)*W8/1000000 -> 58.2426 | T8: =SUM(R8*S8) -> 116.4852 | U8: 1200 | V8: =SUM(T8*U8) -> 139782.24 | W8: 3 | AH8: 133.2
A9: 4 | B9: NECK INSERT- B & P | C9: STEEL | D9: 1,2085 | E9: 8 | F9: + | G9: 2 | H9: 145 | I9: x | J9: 58 | K9: x | L9: 15.41 | N9: Mc Model | O9: =H9+5 -> 150 | P9: =J9+5 -> 63 | Q9: =L9+5 -> 20.41 | R9: =E9+G9 -> 10 | S9: =SUM(O9*P9*Q9)*W9/1000000 -> 1.5526397 | T9: =SUM(R9*S9) -> 15.526397 | U9: 480 | V9: =SUM(T9*U9) -> 7452.6707 | W9: 8.05 | AH9: 15.6
A10: 5 | B10: STRIKER INSERT- B & P* | C10: STEEL | D10: D2 | E10: 20 | F10: + | G10: 4 | H10: 60 | I10: x | J10: 58 | K10: x | L10: 14.7 | M10: 58~60 HRC | O10: =H10+5 -> 65 | P10: =J10+5 -> 63 | Q10: =L10+5 -> 19.7 | R10: =E10+G10 -> 24 | S10: =SUM(O10*P10*Q10)*W10/1000000 -> 0.64940558 | T10: =SUM(R10*S10) -> 15.585734 | U10: 380 | V10: =SUM(T10*U10) -> 5922.5788 | W10: 8.05 | AH10: 14.35
A11: 6 | B11: COOLING PLATE- B & P | C11: STEEL | D11: 1,2085 | E11: 2 | H11: 210 | I11: x | J11: 105 | K11: x | L11: 5 | N11: Mc Model | O11: =H11+5 -> 215 | P11: =J11+5 -> 110 | Q11: =L11+5 -> 10 | R11: =E11+G11 -> 2 | S11: =SUM(O11*P11*Q11)*W11/1000000 -> 1.903825 | T11: =SUM(R11*S11) -> 3.80765 | U11: 480 | V11: =SUM(T11*U11) -> 1827.672 | W11: 8.05 | AH11: 5
A12: 7 | B12: SAND BLASTING SHEET | C12: ALUMINIUM | D12: HOKOTOL/ALUMOLD1-500 | E12: 1 | H12: 1230 | I12: x | J12: 361.954 | K12: x | L12: 10 | O12: =H12+5 -> 1235 | P12: =J12+5 -> 366.954 | Q12: =L12+5 -> 15 | R12: =E12+G12 -> 1 | S12: =SUM(O12*P12*Q12)*W12/1000000 -> 20.393469 | T12: =SUM(R12*S12) -> 20.393469 | U12: 500 | V12: =SUM(T12*U12) -> 10196.734 | W12: 3 | AH12: 10
A13: 8 | B13: PINCH PLATE MC-1 TOP-1(B&P) | C13: STEEL | D13: 1,2085 | E13: 2 | H13: 200 | I13: x | J13: 200 | K13: x | L13: 9.3 | O13: =H13+5 -> 205 | P13: =J13+5 -> 205 | Q13: =L13+5 -> 14.3 | R13: =E13+G13 -> 2 | S13: =SUM(O13*P13*Q13)*W13/1000000 -> 4.8377079 | T13: =SUM(R13*S13) -> 9.6754158 | U13: 480 | V13: =SUM(T13*U13) -> 4644.1996 | W13: 8.05 | AH13: 5
A14: 9 | B14: PINCH PLATE MC-2 TOP&BTM(B) | C14: STEEL | D14: 1,2085 | E14: 1 | H14: 200 | I14: x | J14: 200 | K14: x | L14: 9.3 | O14: =H14+5 -> 205 | P14: =J14+5 -> 205 | Q14: =L14+5 -> 14.3 | R14: =E14+G14 -> 1 | S14: =SUM(O14*P14*Q14)*W14/1000000 -> 4.8377079 | T14: =SUM(R14*S14) -> 4.8377079 | U14: 480 | V14: =SUM(T14*U14) -> 2322.0998 | W14: 8.05 | AH14: 5
A15: 10 | B15: PINCH PLATE MC-3 TOP&BTM(P) | C15: STEEL | D15: 1,2085 | E15: 1 | H15: 200 | I15: x | J15: 200 | K15: x | L15: 9.3 | O15: =H15+5 -> 205 | P15: =J15+5 -> 205 | Q15: =L15+5 -> 14.3 | R15: =E15+G15 -> 1 | S15: =SUM(O15*P15*Q15)*W15/1000000 -> 4.8377079 | T15: =SUM(R15*S15) -> 4.8377079 | U15: 480 | V15: =SUM(T15*U15) -> 2322.0998 | W15: 8.05 | AH15: 5
A16: 11(#A) | B16: 10H7 SCREW PLUGS(PINCH PLATES) | C16: BRASS | D16: BRASS | E16: 150 | I16: Ø | J16: 13 | K16: x | L16: 40 | N16: Order Dia 15x500mm length bar Qty 15 | O16: 15 | P16: 500 | R16: 15 | S16: =SUM(3.14*(O16*O16)/4*P16*W16/1000000) -> 0.77096813 | T16: =SUM(R16*S16) -> 11.564522 | U16: 650 | V16: =SUM(T16*U16) -> 7516.9392 | W16: 8.73
A17: 12(#A) | B17: 8H7 SCREW PLUGS(PINCH PLATES) | C17: BRASS | D17: BRASS | E17: 240 | I17: Ø | J17: 13 | K17: x | L17: 40 | N17: Order Dia 15x500mm length bar Qty 24 | O17: 15 | P17: 500 | R17: 24 | S17: =SUM(3.14*(O17*O17)/4*P17*W17/1000000) -> 0.77096813 | T17: =SUM(R17*S17) -> 18.503235 | U17: 650 | V17: =SUM(T17*U17) -> 12027.103 | W17: 8.73
A18: 13(#A) | B18: 6H7 SCREW PLUGS(PINCH PLATES) | C18: BRASS | D18: BRASS | E18: 50 | I18: Ø | J18: 10 | K18: x | L18: 35 | N18: Order Dia 12x500mm length bar Qty 5 | O18: 12 | P18: 500 | R18: 5 | S18: =SUM(3.14*(O18*O18)/4*P18*W18/1000000) -> 0.4934196 | T18: =SUM(R18*S18) -> 2.467098 | U18: 650 | V18: =SUM(T18*U18) -> 1603.6137 | W18: 8.73
A19: 14(#A) | B19: PINCH PLATE MC FIX-1,2&3 | C19: STEEL | D19: C45 | E19: 1 | H19: 250 | I19: x | J19: 200 | K19: x | L19: 18 | O19: =H19+5 -> 255 | P19: =J19+5 -> 205 | Q19: =L19+5 -> 23 | R19: =E19+G19 -> 1 | S19: =SUM(O19*P19*Q19)*W19/1000000 -> 9.6787163 | T19: =SUM(R19*S19) -> 9.6787163 | U19: 100 | V19: =SUM(T19*U19) -> 967.87163 | W19: 8.05 | AH19: 5
A20: 15(#A) | B20: PINCH PLATE MC FIX-1,2&3 | C20: STEEL | D20: C45 | E20: 1 | H20: 250 | I20: x | J20: 200 | K20: x | L20: 18 | O20: =H20+5 -> 255 | P20: =J20+5 -> 205 | Q20: =L20+5 -> 23 | R20: =E20+G20 -> 1 | S20: =SUM(O20*P20*Q20)*W20/1000000 -> 9.6787163 | T20: =SUM(R20*S20) -> 9.6787163 | U20: 100 | V20: =SUM(T20*U20) -> 967.87163 | W20: 8.05 | AH20: 5
A21: 16(#A) | B21: PINCH PLATE MC FIX-1,2&3 | C21: STEEL | D21: C45 | E21: 1 | H21: 250 | I21: x | J21: 200 | K21: x | L21: 18 | O21: =H21+5 -> 255 | P21: =J21+5 -> 205 | Q21: =L21+5 -> 23 | R21: =E21+G21 -> 1 | S21: =SUM(O21*P21*Q21)*W21/1000000 -> 9.6787163 | T21: =SUM(R21*S21) -> 9.6787163 | U21: 100 | V21: =SUM(T21*U21) -> 967.87163 | W21: 8.05 | AH21: 5
A22: RevA# S.no 11 to 16 added on 16-02-2026 by A.kalyan | O22: Inserts Cost : | V22: =SUM(V6:V21) -> 542517.72
A23: ITEM:- MASK ASSEMBLY
A24: 1(#A) | B24: STRIPPER PLATE* | C24: ALUMINIUM | D24: 5083 | E24: 2 | H24: 1160 | I24: x | J24: 115 | K24: x | L24: 10 | O24: =H24+5 -> 1165 | P24: =J24+5 -> 120 | Q24: =L24+5 -> 15 | R24: =E24+G24 -> 2 | S24: =SUM(O24*P24*Q24)*W24/1000000 -> 6.291 | T24: =SUM(R24*S24) -> 12.582 | U24: 752 | V24: =SUM(T24*U24) -> 9461.664 | W24: 3
A25: 2 | B25: UPPER MASK BUSH SIDE | C25: ALUMINIUM | D25: 5083 | E25: 1 | H25: 1165 | I25: x | J25: 95 | K25: x | L25: 30 | O25: =H25+5 -> 1170 | P25: =J25+5 -> 100 | Q25: =L25+5 -> 35 | R25: =E25+G25 -> 1 | S25: =SUM(O25*P25*Q25)*W25/1000000 -> 12.285 | T25: =SUM(R25*S25) -> 12.285 | U25: 752 | V25: =SUM(T25*U25) -> 9238.32 | W25: 3
A26: 3 | B26: LOWER MASK BUSH SIDE | C26: ALUMINIUM | D26: 5083 | E26: 1 | H26: 1165 | I26: x | J26: 95 | K26: x | L26: 28 | O26: =H26+5 -> 1170 | P26: =J26+5 -> 100 | Q26: =L26+5 -> 33 | R26: =E26+G26 -> 1 | S26: =SUM(O26*P26*Q26)*W26/1000000 -> 11.583 | T26: =SUM(R26*S26) -> 11.583 | U26: 752 | V26: =SUM(T26*U26) -> 8710.416 | W26: 3
A27: 4 | B27: UPPER MASK PIN SIDE | C27: ALUMINIUM | D27: 5083 | E27: 1 | H27: 1165 | I27: x | J27: 95 | K27: x | L27: 30 | O27: =H27+5 -> 1170 | P27: =J27+5 -> 100 | Q27: =L27+5 -> 35 | R27: =E27+G27 -> 1 | S27: =SUM(O27*P27*Q27)*W27/1000000 -> 12.285 | T27: =SUM(R27*S27) -> 12.285 | U27: 752 | V27: =SUM(T27*U27) -> 9238.32 | W27: 3
A28: 5 | B28: LOWER MASK PIN SIDE | C28: ALUMINIUM | D28: 5083 | E28: 1 | H28: 1165 | I28: x | J28: 95 | K28: x | L28: 28 | O28: =H28+5 -> 1170 | P28: =J28+5 -> 100 | Q28: =L28+5 -> 33 | R28: =E28+G28 -> 1 | S28: =SUM(O28*P28*Q28)*W28/1000000 -> 11.583 | T28: =SUM(R28*S28) -> 11.583 | U28: 752 | V28: =SUM(T28*U28) -> 8710.416 | W28: 3
A29: 6 | B29: NECK PART B & P | C29: ALUMINIUM | D29: 5083 | E29: 8 | H29: 103 | I29: x | J29: 78.6 | K29: x | L29: 42 | N29: Mc Model | O29: =H29+5 -> 108 | P29: =J29+5 -> 83.6 | Q29: =L29+5 -> 47 | R29: =E29+G29 -> 8 | S29: =SUM(O29*P29*Q29)*W29/1000000 -> 1.2730608 | T29: =SUM(R29*S29) -> 10.184486 | U29: 752 | V29: =SUM(T29*U29) -> 7658.7338 | W29: 3
A30: 7 | B30: MOUNTING PLATE-1 (PARISON SIDE) | C30: ALUMINIUM | D30: 5083 | E30: 1 | H30: 225 | I30: x | J30: 159 | K30: x | L30: 40 | O30: =H30+5 -> 230 | P30: =J30+5 -> 164 | Q30: =L30+5 -> 45 | R30: =E30+G30 -> 1 | S30: =SUM(O30*P30*Q30)*W30/1000000 -> 5.0922 | T30: =SUM(R30*S30) -> 5.0922 | U30: 752 | V30: =SUM(T30*U30) -> 3829.3344 | W30: 3
A31: 8 | B31: MOUNTING PLATE-2 (TAKE OUT SIDE) | C31: ALUMINIUM | D31: 5083 | E31: 1 | H31: 255 | I31: x | J31: 159 | K31: x | L31: 40 | O31: =H31+5 -> 260 | P31: =J31+5 -> 164 | Q31: =L31+5 -> 45 | R31: =E31+G31 -> 1 | S31: =SUM(O31*P31*Q31)*W31/1000000 -> 5.7564 | T31: =SUM(R31*S31) -> 5.7564 | U31: 752 | V31: =SUM(T31*U31) -> 4328.8128 | W31: 3
A32: 9 | B32: MOUNTING_PUNCH_PLATE | C32: ALUMINIUM | D32: 5083 | E32: 1 | H32: 1150 | I32: x | J32: 107.8 | K32: x | L32: 30 | O32: =H32+5 -> 1155 | P32: =J32+5 -> 112.8 | Q32: =L32+5 -> 35 | R32: =E32+G32 -> 1 | S32: =SUM(O32*P32*Q32)*W32/1000000 -> 13.67982 | T32: =SUM(R32*S32) -> 13.67982 | U32: 752 | V32: =SUM(T32*U32) -> 10287.225 | W32: 3
A33: 10 | B33: NECK PUNCH 1 | C33: ALUMINIUM | D33: 5083 | E33: 1 | H33: 578 | I33: x | J33: 80 | K33: x | L33: 50 | O33: =H33+5 -> 583 | P33: =J33+5 -> 85 | Q33: =L33+5 -> 55 | R33: =E33+G33 -> 1 | S33: =SUM(O33*P33*Q33)*W33/1000000 -> 8.176575 | T33: =SUM(R33*S33) -> 8.176575 | U33: 752 | V33: =SUM(T33*U33) -> 6148.7844 | W33: 3
A34: 11 | B34: NECK PUNCH 2 | C34: ALUMINIUM | D34: 5083 | E34: 1 | H34: 578 | I34: x | J34: 80 | K34: x | L34: 50 | O34: =H34+5 -> 583 | P34: =J34+5 -> 85 | Q34: =L34+5 -> 55 | R34: =E34+G34 -> 1 | S34: =SUM(O34*P34*Q34)*W34/1000000 -> 8.176575 | T34: =SUM(R34*S34) -> 8.176575 | U34: 752 | V34: =SUM(T34*U34) -> 6148.7844 | W34: 3
A35: 12 | B35: PUNCH DISTANCE BOLTS | C35: STEEL | D35: 1,2085 | E35: 10 | I35: Ø | J35: 22 | K35: x | L35: 163 | O35: =J35+5 -> 27 | P35: =L35+5 -> 168 | R35: =E35+G35 -> 10 | S35: =SUM(3.14*(O35*O35)/4*P35*W35/1000000) -> 0.77393119 | T35: =SUM(R35*S35) -> 7.7393119 | U35: 480 | V35: =SUM(T35*U35) -> 3714.8697 | W35: 8.05
A36: 13 | B36: COVERING SHEET (BENDING SHEET) | C36: ALUMINIUM | D36: 5083 | E36: 1 | H36: 183 | I36: x | J36: 86.2124 | K36: x | L36: 2 | N36: 2mm Sheet | O36: =H36+5 -> 188 | P36: =J36+5 -> 91.2124 | Q36: =L36 -> 2 | R36: =E36+G36 -> 1 | S36: =SUM(O36*P36*Q36)*W36/1000000 -> 0.10288759 | T36: =SUM(R36*S36) -> 0.10288759 | U36: 550 | V36: =SUM(T36*U36) -> 56.588173 | W36: 3
A37: 14 | B37: CONNECTION_SHEET_MASK_ARM | C37: ALUMINIUM | D37: 5083 | E37: 1 | H37: 390 | I37: x | J37: 127.5 | K37: x | L37: 5 | N37: 5mm Sheet | O37: =H37+5 -> 395 | P37: =J37+5 -> 132.5 | Q37: =L37 -> 5 | R37: =E37+G37 -> 1 | S37: =SUM(O37*P37*Q37)*W37/1000000 -> 0.7850625 | T37: =SUM(R37*S37) -> 0.7850625 | U37: 550 | V37: =SUM(T37*U37) -> 431.78438 | W37: 3
W38: 3
A39: RevA# S.no1 Sizes modified 16-02-2026 by A.kalyan need to order new | O39: Mask Parts Cost : | V39: =SUM(V24:V38) -> 87964.053
A40: PREPARED BY : Srikanth | C40: Date : 20-12-25 | N40: APPROVED BY : Srikanth | O40: Total Amount: | V40: =V39+V22 -> 630481.77
...

Sheet Mold Base Parts 
A1: PRATHIRAJ METAL MASTERS PVT.LTD
A2: PART LIST
A3: TOOL NO : BM454 Veedol 600ml M01 08Cavity Mold SEB101 FN
A4: ITEM:-MOLD BASE PARTS
A5: S.NO | B5: DESCRIPTION | C5: MATERIAL | D5: GRADE | E5: QTY | H5: FINISHED SIZES | N5: REMARKS | O5: Length/Dia | P5: Height | Q5: Width | R5: Qty | S5: Weight | T5: Total Weight | U5: Rate | V5: Amount
A6: 1 | B6: COOLING BLOCK | C6: STEEL | D6: 1.2085 | E6: 4 | H6: 135 | I6: x | J6: 135 | K6: x | L6: 40 | O6: =H6+5 -> 140 | P6: =J6+5 -> 140 | Q6: =L6+5 -> 45 | R6: =E6+G6 -> 4 | S6: =SUM(O6*P6*Q6)*W6/1000000 -> 7.1001 | T6: =SUM(R6*S6) -> 28.4004 | U6: 480 | V6: =SUM(T6*U6) -> 13632.192 | W6: 8.05
A7: 2 | B7: STRAP CLAMP | C7: ALUMINIUM | D7: ALUMINIUM | E7: 1 | H7: 252 | I7: x | J7: 110 | K7: x | L7: 40 | O7: =H7+5 -> 257 | P7: =J7+5 -> 115 | Q7: =L7+5 -> 45 | R7: =E7+G7 -> 1 | S7: =SUM(O7*P7*Q7)*W7/1000000 -> 3.989925 | T7: =SUM(R7*S7) -> 3.989925 | U7: 500 | V7: =SUM(T7*U7) -> 1994.9625 | W7: 3
A8: 3 | B8: SUPPORT BLOCK | C8: STEEL | D8: 1.2085 | E8: 2 | H8: 213 | I8: x | J8: 62 | K8: x | L8: 10 | N8: Mc Model | O8: =H8+5 -> 218 | P8: =J8+5 -> 67 | Q8: =L8+5 -> 15 | R8: =E8+G8 -> 2 | S8: =SUM(O8*P8*Q8)*W8/1000000 -> 1.7636745 | T8: =SUM(R8*S8) -> 3.527349 | U8: 480 | V8: =SUM(T8*U8) -> 1693.1275 | W8: 8.05
A9: 4 | B9: AIR DEFLECTOR SHEET | C9: ALUMINIUM | D9: ALUMINIUM | E9: 1 | H9: 222.704 | I9: x | J9: 29 | K9: x | L9: 3 | N9: 3mm Sheet | O9: =H9+5 -> 227.704 | P9: =J9+5 -> 34 | Q9: =L9+0 -> 3 | R9: =E9+G9 -> 1 | S9: =SUM(O9*P9*Q9)*W9/1000000 -> 0.069677424 | T9: =SUM(R9*S9) -> 0.069677424 | U9: 500 | V9: =SUM(T9*U9) -> 34.838712 | W9: 3
A10: 5 | B10: DISTANCE PIN WITH CUT OUT* | C10: STEEL | D10: 1,2085 | E10: 4 | I10: Ø | J10: 20 | K10: x | L10: 68.8 | O10: =J10+5 -> 25 | P10: =L10+5 -> 73.8 | R10: =E10+G10 -> 4 | S10: =SUM(3.14*(O10*O10)/4*P10*W10/1000000) -> 0.29147541 | T10: =SUM(R10*S10) -> 1.1659016 | U10: 480 | V10: =SUM(T10*U10) -> 559.63278 | W10: 8.05
A11: 6 | B11: DISTANCE PIN* | C11: STEEL | D11: 1.2085 | E11: 4 | I11: Ø | J11: 20 | K11: x | L11: 62.8 | O11: =J11+5 -> 25 | P11: =L11+5 -> 67.8 | R11: =E11+G11 -> 4 | S11: =SUM(3.14*(O11*O11)/4*P11*W11/1000000) -> 0.26777822 | T11: =SUM(R11*S11) -> 1.0711129 | U11: 480 | V11: =SUM(T11*U11) -> 514.13418 | W11: 8.05
A12: 7 | B12: BLOCKING WASHER* | C12: STEEL | D12: 1.2085 | E12: 1 | H12: 150 | I12: x | J12: 120 | K12: x | L12: 5 | N12: Mc Model | O12: =H12+5 -> 155 | P12: =J12+5 -> 125 | Q12: =L12+0 -> 5 | R12: =E12+G12 -> 1 | S12: =SUM(O12*P12*Q12)*W12/1000000 -> 0.77984375 | T12: =SUM(R12*S12) -> 0.77984375 | U12: 480 | V12: =SUM(T12*U12) -> 374.325 | W12: 8.05
A13: 8 | B13: INNER LEAK TESTING HEAD | C13: FIBER | D13: NYLON | E13: 12 | F13: + | G13: 2 | I13: Ø | J13: 31.4 | K13: x | L13: 55 | N13: Order Dia 35X410L bar qty no's | O13: 35 | P13: 410 | R13: 2 | S13: =SUM(3.14*(O13*O13)/4*P13*W13/1000000) -> 0.39426625 | T13: =SUM(R13*S13) -> 0.7885325 | U13: 500 | V13: =SUM(T13*U13) -> 394.26625 | W13: 1
A14: 9 | B14: NECK INSERT EDM | C14: STEEL | D14: C45 | E14: 1 | H14: 110 | I14: x | J14: 85 | K14: x | L14: 20 | O14: =H14+5 -> 115 | P14: =J14+5 -> 90 | Q14: =L14+0 -> 20 | R14: =E14+G14 -> 1 | S14: =SUM(O14*P14*Q14)*W14/1000000 -> 1.66635 | T14: =SUM(R14*S14) -> 1.66635 | U14: 100 | V14: =SUM(T14*U14) -> 166.635 | W14: 8.05
A15: 10 | B15: NECK INSERT ANGLE EDM | C15: STEEL | D15: C45 | E15: 1 | H15: 110 | I15: x | J15: 100 | K15: x | L15: 20 | O15: =H15+5 -> 115 | P15: =J15+5 -> 105 | Q15: =L15+0 -> 20 | R15: =E15+G15 -> 1 | S15: =SUM(O15*P15*Q15)*W15/1000000 -> 1.944075 | T15: =SUM(R15*S15) -> 1.944075 | U15: 100 | V15: =SUM(T15*U15) -> 194.4075 | W15: 8.05
A16: 11 | B16: NECK INSERT MC | C16: STEEL | D16: C45 | E16: 1 | H16: 200 | I16: x | J16: 120 | K16: x | L16: 20 | O16: =H16+5 -> 205 | P16: =J16+5 -> 125 | Q16: =L16+0 -> 20 | R16: =E16+G16 -> 1 | S16: =SUM(O16*P16*Q16)*W16/1000000 -> 4.125625 | T16: =SUM(R16*S16) -> 4.125625 | U16: 100 | V16: =SUM(T16*U16) -> 412.5625 | W16: 8.05
A18: #RevA Mold Base Parts Added by A.Kalyan on 16-02-2026
A19: PREPARED BY : A.Kalyan | C19: Date : 16-02-2026 | N19: APPROVED BY : SRIKANTH | O19: Total Amount: | V19: =SUM(V6:V17) -> 19971.084
A43: 9 | B43: PINCH_PLATES_BODY- BL,BR, PL & PR | C43: BERILIUM | D43: BERILIUM COPPER | E43: 6 | F43: + | G43: 0 | H43: 191 | I43: x | J43: 191 | K43: x | L43: 10 | N43: Mc Model | O43: =H43+0.5 -> 191.5 | P43: =J43+0.5 -> 191.5 | Q43: =L43+0.5 -> 10.5 | R43: =E43+G43 -> 6 | S43: =SUM(O43*P43*Q43)*W43/1000000 -> 3.2190901 | T43: =SUM(R43*S43) -> 19.314541 | U43: 5500 | V43: =SUM(T43*U43) -> 106229.97 | W43: 8.36 | X43: only 1mm stock
A44: 9 | B44: PINCH_PLATES_BODY- BL,BR, PL & PR | C44: BERILIUM | D44: BERILIUM COPPER | E44: 6 | F44: + | G44: 0 | H44: 195 | I44: x | J44: 170 | K44: x | L44: 10 | N44: Mc Model | O44: =H44+0.5 -> 195.5 | P44: =J44+0.5 -> 170.5 | Q44: =L44+0.5 -> 10.5 | R44: =E44+G44 -> 6 | S44: =SUM(O44*P44*Q44)*W44/1000000 -> 2.9259488 | T44: =SUM(R44*S44) -> 17.555693 | U44: 5500 | V44: =SUM(T44*U44) -> 96556.31 | W44: 8.36 | X44: only 1mm stock
A45: 9 | B45: PINCH_PLATES_BODY- BL,BR, PL & PR | C45: BERILIUM | D45: BERILIUM COPPER | E45: 12 | F45: + | G45: 0 | H45: 160 | I45: x | J45: 90 | K45: x | L45: 10 | N45: Mc Model | O45: =H45+0.5 -> 160.5 | P45: =J45+0.5 -> 90.5 | Q45: =L45+0.5 -> 10.5 | R45: =E45+G45 -> 12 | S45: =SUM(O45*P45*Q45)*W45/1000000 -> 1.2750264 | T45: =SUM(R45*S45) -> 15.300317 | U45: 5500 | V45: =SUM(T45*U45) -> 84151.745 | W45: 8.36 | X45: only 1mm stock

Sheet Standard Parts 
A1: PRATHIRAJ METAL MASTERS PVT.LTD
A2: PART LIST
A3: TOOL NO :BM454 Veedol 600ml M01 08Cavity Mold SEB101 FN | K3: STCW28-125
A4: ITEM:- STANDARD PARTS - MOLD
A5: S.NO | B5: DESCRIPTION | C5: PART TYPE | D5: QTY | G5: PART NUMBER | H5: SUPPLIER | I5: REMARKS | J5: Qty | K5: Rate | L5: Amount
A6: 1 | B6: Dowel Pins High precision Type/4Dia | C6: STD | D6: 120 | E6: + | F6: 20 | G6: MS4-25 | H6: MISUMI | I6: Pinch Plates | J6: =F6+D6 -> 140 | K6: 70 | L6: =J6*K6 -> 9800
A7: 2 | B7: Dowel Pins High precision Type/5Dia | C7: STD | D7: 20 | E7: + | F7: 5 | G7: MS5-25 | H7: MISUMI | I7: Pinch Plates | J7: =F7+D7 -> 25 | K7: 70 | L7: =J7*K7 -> 1750
A8: 3 | B8: Dowel Pins High precision Type/5Dia | C8: STD | D8: 4 | E8: + | F8: 6 | G8: MSTP10-45 | H8: MISUMI | I8: BASE INSERT - BOTTOM INSERT | J8: =F8+D8 -> 10 | K8: 70 | L8: =J8*K8 -> 700
A9: 4 | B9: Socket Head Cap Screws/Black Oxide | C9: STD | D9: 5 | G9: CBSS5-10 | H9: MISUMI | I9: DEFLECTOR SHEET | J9: =F9+D9 -> 5 | K9: 55 | L9: =J9*K9 -> 275
A10: 5 | B10: Socket Head Cap Screws/Black Oxide | C10: STD | D10: 32 | E10: + | F10: 20 | G10: CBSS5-12 | H10: MISUMI | I10: COOLING PLATE - BODY INSERT | J10: =F10+D10 -> 52 | K10: 55 | L10: =J10*K10 -> 2860
A11: 6 | B11: SCREW PLUGS | C11: STD | D11: 8 | E11: + | F11: 4 | G11: MSWS12 6 | H11: MISUMI | I11: BODY INSERT | J11: =F11+D11 -> 12 | K11: 72 | L11: =J11*K11 -> 864
A12: 7 | B12: O-RING-1 B&P | C12: STD | D12: 16 | E12: + | F12: 5 | G12: GROOVE ID Ø26.3x2.0 | H12: FIG -3 (SPARE-AGE) | I12: COOLING PLATE - BODY INSERT | J12: =F12+D12 -> 21 | K12: 30 | L12: =J12*K12 -> 630
A13: 8 | B13: O-RING-2 B&P | C13: STD | D13: 16 | E13: + | F13: 5 | G13: GROOVE ID Ø36.7x2.0 | H13: FIG -3 (SPARE-AGE) | I13: NECK INSERT - BODY INSERT | J13: =F13+D13 -> 21 | K13: 50 | L13: =J13*K13 -> 1050
A14: 9 | B14: O-RING-3 B&P | C14: STD | D14: 16 | E14: + | F14: 5 | G14: GROOVE ID Ø27.90x2.0 | H14: FIG -3 (SPARE-AGE) | I14: BASE INSERT - BODY INSERT | J14: =F14+D14 -> 21 | K14: 50 | L14: =J14*K14 -> 1050
A15: 10 | B15: O-RING-5 B&P | C15: STD | D15: 16 | E15: + | F15: 5 | G15: GROOVE ID Ø13.7x2.0 | H15: FIG -3 (SPARE-AGE) | I15: BASE INSERT - BODY INSERT | J15: =F15+D15 -> 21 | K15: 30 | L15: =J15*K15 -> 630
A16: 11 | B16: O-RING-6 B&P | C16: STD | D16: 16 | E16: + | F16: 5 | G16: GROOVE ID Ø14.1x2.0 | H16: FIG -3 (SPARE-AGE) | I16: BASE INSERT - BODY INSERT | J16: =F16+D16 -> 21 | K16: 30 | L16: =J16*K16 -> 630
A17: 12 | B17: O-RING-4 B&P | C17: STD | D17: 16 | E17: + | F17: 5 | G17: GROOVE ID Ø26.0x2.0 | H17: FIG -3 (SPARE-AGE) | I17: BASE INSERT - BODY INSERT | J17: =F17+D17 -> 21 | K17: 50 | L17: =J17*K17 -> 1050
A18: 13 | B18: O-RING-4 B&P | C18: STD | D18: 16 | E18: + | F18: 5 | G18: GROOVE ID Ø54.4x2.0 | H18: FIG -3 (SPARE-AGE) | I18: BASE INSERT - BODY INSERT | J18: =F18+D18 -> 21 | K18: 50 | L18: =J18*K18 -> 1050
A19: 14 | B19: O-RING-7 B&P | C19: STD | D19: 24 | E19: + | F19: 3 | G19: GROOVE ID Ø27x2.0 | H19: FIG -3 (SPARE-AGE) | I19: Cooling Block, Base,Bottom Ins | J19: =F19+D19 -> 27 | K19: 50 | L19: =J19*K19 -> 1350
A20: 15 | B20: DATE INSERTS | C20: STD | D20: 9 | E20: + | F20: 0 | G20: V3.3/10x12 | I20: Vijay deep (Please confirm with design) | J20: =F20+D20 -> 9 | K20: 50 | L20: =J20*K20 -> 450
A21: E2420/10/26 (Alternate code for meusburger for Date Inserts) | J21: Mold PartsCost | L21: =SUM(L6:L19) -> 23689
A22: ITEM:- STANDARD PARTS - MASK
A23: S.NO | B23: DESCRIPTION | C23: MATERIAL | D23: QTY | G23: FINISHED SIZES | H23: SUPPLIER | I23: REMARKS | J23: Qty | K23: Rate | L23: Amount
A24: 1 | B24: Dowel ( Stripper plate to Holder )* | C24: STD | D24: 4 | E24: + | F24: 2 | G24: MSTP6 20 | H24: MISUMI | J24: =F24+D24 -> 6 | K24: 70 | L24: =J24*K24 -> 420
A25: 2 | B25: Dowel ( Mask Arms to Machine Platen )* | C25: STD | D25: 8 | E25: + | F25: 2 | G25: MSTP10 30 | H25: MISUMI | J25: =F25+D25 -> 10 | K25: 70 | L25: =J25*K25 -> 700
A26: 3 | B26: Dowel ( Mounting plate2 to Machine Platen )* | C26: STD | D26: 8 | E26: + | F26: 2 | G26: MSTP10 40 | H26: MISUMI | J26: =F26+D26 -> 10 | K26: 70 | L26: =J26*K26 -> 700
A27: 4 | B27: Dowel ( Mounting plate1 to Machine Platen )* | C27: STD | D27: 8 | E27: + | F27: 2 | G27: MSTP10 60 | H27: MISUMI | J27: =F27+D27 -> 10 | K27: 70 | L27: =J27*K27 -> 700
A28: 5 | B28: Dowel ( Mask Arms to Maks )* | C28: STD | D28: 4 | E28: + | F28: 4 | G28: MSTP8 35 | H28: MISUMI | J28: =F28+D28 -> 8 | K28: 70 | L28: =J28*K28 -> 560
A29: 6 | B29: Dowel ( Mounting Plate to Maks ) * | C29: STD | D29: 4 | E29: + | F29: 4 | G29: MSTP8 35 | H29: MISUMI | J29: =F29+D29 -> 8 | K29: 70 | L29: =J29*K29 -> 560
A30: 7 | B30: Dowel ( Arms to Connecting Sheet )* | C30: STD | D30: 4 | E30: + | F30: 4 | G30: MSTP6 15 | H30: MISUMI | J30: =F30+D30 -> 8 | K30: 70 | L30: =J30*K30 -> 560
A31: 8 | B31: SCREW PLUGS* | C31: STD | D31: 6 | E31: + | F31: 2 | G31: MSWS12 6 | H31: MISUMI | J31: =F31+D31 -> 8 | K31: 70 | L31: =J31*K31 -> 560
A32: 9 | B32: SCREW PLUGS (1/4bsp) | C32: STD | D32: 20 | G32: D-MSW2 | H32: MISUMI | I32: - | J32: =F32+D32 -> 20 | K32: 50 | L32: =J32*K32 -> 1000
A33: 10 | B33: SCREW PLUGS (1/8bsp) | C33: STD | D33: 20 | G33: D-MSW1 | H33: MISUMI | I33: - | J33: =F33+D33 -> 20 | K33: 50 | L33: =J33*K33 -> 1000
A35: ITEM: IN House STD parts/Mold
A36: 1 | B36: 3/4" BSP plug | C36: STD | D36: 28 | E36: + | F36: 2 | I36: ALPLA/in house | J36: =F36+D36 -> 30 | K36: 300 | L36: =J36*K36 -> 9000
A37: 2 | B37: THREAD LESS PLUG Ø12 | C37: STD | D37: 64 | E37: + | F37: 4 | I37: ALPLA/in house | J37: =F37+D37 -> 68 | K37: 200 | L37: =J37*K37 -> 13600
A38: 3 | B38: GUIDE PILLAR Ø12 UNIT | C38: STD | D38: 4 | I38: ALPLA/in house | J38: =F38+D38 -> 4 | K38: 400 | L38: =J38*K38 -> 1600
A39: 4 | B39: GUIDE BUSH Ø12 UNIT | C39: STD | D39: 8 | I39: ALPLA/in house | J39: =F39+D39 -> 8 | K39: 400 | L39: =J39*K39 -> 3200
A40: 5 | B40: SHOR COUNTER & Pin | C40: STD | D40: 1 | I40: meusburger/in house | J40: =F40+D40 -> 1 | K40: 200 | L40: =J40*K40 -> 200
A41: ITEM: IN House STD parts/Mask
...

Sheet Fastners
A1: PRATHIRAJ METAL MASTERS PVT.LTD
A2: PART LIST
A3: TOOL NO : BM454 Veedol 600ml M01 08Cavity Mold SEB101 FN | K3: STCW28-125
A4: ITEM:- FASTNERS- MOLD
A5: S.NO | B5: DESCRIPTION | C5: PART TYPE | D5: QTY | G5: PART NUMBER | H5: SUPPLIER | I5: REMARKS | J5: Qty | K5: Rate | L5: Amount
A6: 1 | B6: SHCS Screw | C6: STD | D6: 4 | E6: + | F6: 2 | G6: M12X60 | H6: unbrako | I6: Strap clamp | J6: =F6+D6 -> 6 | K6: 40 | L6: =J6*K6 -> 240
A7: 2 | B7: SHCS Screw | C7: STD | D7: 16 | E7: + | F7: 4 | G7: M5X20 | H7: unbrako | I7: SUPPORT BLOCK | J7: =F7+D7 -> 20 | K7: 10 | L7: =J7*K7 -> 200
A8: 3 | B8: SHCS Screw | C8: STD | D8: 24 | E8: + | F8: 4 | G8: M8X45 | H8: unbrako | I8: COOLING BLOCKS | J8: =F8+D8 -> 28 | K8: 15 | L8: =J8*K8 -> 420
A9: 4 | B9: SHCS Screw | C9: STD | D9: 9 | E9: + | F9: 1 | G9: M8X16 | H9: unbrako | I9: BLOCKING WASHER | J9: =F9+D9 -> 10 | K9: 10 | L9: =J9*K9 -> 100
A10: 5 | B10: SHCS Screw | C10: STD | D10: 32 | E10: + | F10: 4 | G10: M5X12 | H10: unbrako | I10: STRIKER INSERT - NECK INSERT | J10: =F10+D10 -> 36 | K10: 10 | L10: =J10*K10 -> 360
A11: 6 | B11: SHCS Screw | C11: STD | D11: 64 | E11: + | F11: 4 | G11: M5X20 | H11: unbrako | I11: NECK INSERT - BODY INSERT | J11: =F11+D11 -> 68 | K11: 10 | L11: =J11*K11 -> 680
A12: 7 | B12: SHCS Screw | C12: STD | D12: 16 | E12: + | F12: 2 | G12: M5X50 | H12: unbrako | I12: BODY INSERT - NECK INSERT | J12: =F12+D12 -> 18 | K12: 15 | L12: =J12*K12 -> 270
A13: 8 | B13: SHCS Screw | C13: STD | D13: 28 | E13: + | F13: 4 | G13: M8X50 | H13: unbrako | I13: BASE INSERT - BOTTOM INSERT | J13: =F13+D13 -> 32 | K13: 20 | L13: =J13*K13 -> 640
A14: 9 | B14: SHCS Screw | C14: STD | D14: 20 | E14: + | F14: 2 | G14: M8X30 | H14: unbrako | I14: BODY INSERT - BASE INSERT | J14: =F14+D14 -> 22 | K14: 16 | L14: =J14*K14 -> 352
A15: 10 | B15: SHCS Screw | C15: STD | D15: 12 | E15: + | F15: 2 | G15: M8X30 | H15: unbrako | I15: BODY INSERT- BOTTOM INSERT | J15: =F15+D15 -> 14 | K15: 16 | L15: =J15*K15 -> 224
A16: 11 | B16: SHCS Screw | C16: STD | D16: 34 | E16: + | F16: 4 | G16: M10X120 | H16: unbrako | I16: BOTTOM INSERT - BODY INSERT | J16: =F16+D16 -> 38 | K16: 99 | L16: =J16*K16 -> 3762
J17: Mold PartsCost | L17: =SUM(L6:L16) -> 7248
A18: ITEM:- FASTNERS-MASK
A19: S.NO | B19: DESCRIPTION | C19: PART TYPE | D19: QTY | G19: PART NUMBER | H19: SUPPLIER | I19: REMARKS | J19: Qty | K19: Rate | L19: Amount
A20: 1 | B20: SHC SCREW* | C20: STD | D20: 20 | E20: + | F20: 0 | G20: M8X20 | H20: unbrako | I20: *STRIPPER PLATE | J20: =F20+D20 -> 20 | K20: 10 | L20: =J20*K20 -> 200
A21: 2 | B21: CSK SCREW | C21: STD | D21: 4 | G21: M12X50 | H21: unbrako | I21: STRIPPER PLATE | J21: =F21+D21 -> 4 | K21: 50 | L21: =J21*K21 -> 200
A22: 3 | B22: M12 SELF LOCKING NUT* | C22: STD | D22: 4 | G22: M12 | H22: unbrako | I22: *STRIPPER PLATE | J22: =F22+D22 -> 4 | K22: 50 | L22: =J22*K22 -> 200
A23: 4 | B23: SHCS SCREW* | C23: STD | D23: 12 | E23: + | F23: 0 | G23: M10X35 | H23: unbrako | I23: MASK ARMS TO MACHINE PLATEN | J23: =F23+D23 -> 12 | K23: 20 | L23: =J23*K23 -> 240
A24: 5 | B24: SHCS SCREW | C24: STD | D24: 4 | E24: + | F24: 0 | G24: M10X60 | H24: unbrako | I24: UPPER & LOWER MASK BUSH SIDE TO MASK ARM | J24: =F24+D24 -> 4 | K24: 30 | L24: =J24*K24 -> 120
A25: 6 | B25: SHCS SCREW | C25: STD | D25: 4 | E25: + | F25: 0 | G25: M10X60 | H25: unbrako | I25: LOWER MASK PIN SIDE TO MOUNTING PLATE | J25: =F25+D25 -> 4 | K25: 30 | L25: =J25*K25 -> 120
A26: 7 | B26: SHCS SCREW | C26: STD | D26: 32 | E26: + | F26: 0 | G26: M8X30 | H26: unbrako | I26: NECK PART TO MASK | J26: =F26+D26 -> 32 | K26: 10 | L26: =J26*K26 -> 320
A27: 8 | B27: SHC SCREW* | C27: STD | D27: 10 | G27: M10X40 | H27: unbrako | I27: MC PLATEN TO MOUNTING PLATE 2 | J27: =F27+D27 -> 10 | K27: 22 | L27: =J27*K27 -> 220
A28: 9 | B28: SHC SCREW* | C28: STD | D28: 10 | G28: M10X60 | H28: unbrako | I28: MC PLATEN TO MOUNTING PLATE 1 | J28: =F28+D28 -> 10 | K28: 28 | L28: =J28*K28 -> 280
A29: 10 | B29: SHCS SCREW* | C29: STD | D29: 10 | E29: + | F29: 0 | G29: M8X30 | H29: unbrako | I29: MOUNTING PLATE PUNCH TO DISTANCE_PIN | J29: =F29+D29 -> 10 | K29: 10 | L29: =J29*K29 -> 100
A30: 11 | B30: SHCS SCREW | C30: STD | D30: 10 | E30: + | F30: 0 | G30: M8X45 | H30: unbrako | I30: NECKPUNCH TO DISTANCE_PIN | J30: =F30+D30 -> 10 | K30: 15 | L30: =J30*K30 -> 150
A31: 12 | B31: GRUB SCREW* | C31: STD | D31: 32 | E31: + | F31: 5 | G31: M5X8 | H31: unbrako | I31: NECK PUNCH 1&2 | J31: =F31+D31 -> 37 | K31: 6 | L31: =J31*K31 -> 222
A32: 13 | B32: SHC SCREW* | C32: STD | D32: 8 | G32: M5X10 | H32: unbrako | I32: Covering sheet to Mounting Plate | J32: =F32+D32 -> 8 | K32: 6 | L32: =J32*K32 -> 48
A33: #RevA Mold Base Parts Added by A.Kalyan on 16-02-2026 | J33: Mask parts Cost | L33: =SUM(L20:L32) -> 2420
A34: PREPARED BY :-A.Kalyan | C34: Date : 16-06-25 | I34: APPROVED BY :- Srikanth | J34: Total Cost | L34: =L17+L33 -> 9668
A62: 11 | B62: SHCS SCREW* | C62: STD | D62: 10 | G62: M8X16 | I62: CONNECTING SHEET | J62: =F62+D62 -> 10 | K62: 10 | L62: =J62*K62 -> 100

Sheet Elec
A1: PRATHIRAJ METAL MASTERS PVT.LTD
A2: PART LIST (only for rawmaterial)
A3: TOOL NO :BM454 Veedol 600ml M01 08Cavity Mold SEB101 FN
A4: ITEM:- Electrodes
A5: S.NO | B5: DESCRIPTION | C5: MATERIAL | D5: QTY | I5: FINISHED SIZES | N5: Spark Gap | O5: EDM | P5: PROCESS TO BE DONE | Q5: REMARKS | S5: Length/Dia | T5: Height | U5: Width | V5: Qty | W5: Weight | X5: Total Weight | Y5: Rate | Z5: Amount
A6: 1 | B6: E01_Groove_elec | C6: COPPER | G6: 3 | H6: F | J6: ø | K6: 45 | L6: x | M6: 26 | N6: NO Gap | O6: Striker INSERT B&P | P6: CNC Turning | S6: =K6+5 -> 50 | T6: =K6+5 -> 50 | V6: =D6+G6 -> 3 | W6: =SUM(3.14*(S6*S6)/4*T6*8/1000000) -> 0.785 | X6: =SUM(V6*W6) -> 2.355 | Y6: 1100 | Z6: =SUM(X6*Y6) -> 2590.5
A7: 2 | B7: E02_Full Thread Elec | C7: COPPER | D7: 3 | E7: R | F7: + | G7: 3 | H7: F | I7: 60 | J7: x | K7: 50 | L7: x | M7: 12 | N7: R0.25/F0.09/SIDE | O7: NECK INSERT B & P | P7: CNC Milling | S7: =I7+5 -> 65 | T7: =K7+5 -> 55 | U7: =M7 -> 12 | V7: =D7+G7 -> 6 | W7: =SUM(S7*T7*U7)*9/1000000 -> 0.3861 | X7: =SUM(V7*W7) -> 2.3166 | Y7: 1100 | Z7: =SUM(X7*Y7) -> 2548.26
A8: 3 | B8: E03_Thread End Elec | C8: COPPER | D8: 3 | E8: R | F8: + | G8: 3 | H8: F | I8: 60 | J8: x | K8: 50 | L8: x | M8: 12 | N8: R0.25/F0.09/SIDE | O8: NECK INSERT B | P8: CNC Milling | S8: =I8+5 -> 65 | T8: =K8+5 -> 55 | U8: =M8 -> 12 | V8: =D8+G8 -> 6 | W8: =SUM(S8*T8*U8)*9/1000000 -> 0.3861 | X8: =SUM(V8*W8) -> 2.3166 | Y8: 1100 | Z8: =SUM(X8*Y8) -> 2548.26
A9: 4 | B9: E05_Snapper ring Elec | C9: COPPER | D9: 3 | E9: R | F9: + | G9: 3 | H9: F | I9: 70 | J9: x | K9: 50 | L9: x | M9: 12 | N9: R0.25/F0.09/SIDE | O9: NECK INSERT B & P | P9: CNC Milling | S9: =I9+5 -> 75 | T9: =K9+5 -> 55 | U9: =M9 -> 12 | V9: =D9+G9 -> 6 | W9: =SUM(S9*T9*U9)*9/1000000 -> 0.4455 | X9: =SUM(V9*W9) -> 2.673 | Y9: 1100 | Z9: =SUM(X9*Y9) -> 2940.3
A10: 5 | B10: E06_Thread start -1 Elec | C10: COPPER | D10: 2 | E10: R | F10: + | G10: 3 | H10: F | I10: 60 | J10: x | K10: 50 | L10: x | M10: 12 | N10: R0.25/F0.09/SIDE | O10: NECK INSERT B | P10: CNC Milling | S10: =I10+5 -> 65 | T10: =K10+5 -> 55 | U10: =M10 -> 12 | V10: =D10+G10 -> 5 | W10: =SUM(S10*T10*U10)*9/1000000 -> 0.3861 | X10: =SUM(V10*W10) -> 1.9305 | Y10: 1100 | Z10: =SUM(X10*Y10) -> 2123.55
A11: 6 | B11: E07_Thread start -1 Elec | C11: COPPER | D11: 2 | E11: R | F11: + | G11: 3 | H11: F | I11: 60 | J11: x | K11: 50 | L11: x | M11: 12 | N11: R0.25/F0.09/SIDE | O11: NECK INSERT B | P11: CNC Milling | S11: =I11+5 -> 65 | T11: =K11+5 -> 55 | U11: =M11 -> 12 | V11: =D11+G11 -> 5 | W11: =SUM(S11*T11*U11)*9/1000000 -> 0.3861 | X11: =SUM(V11*W11) -> 1.9305 | Y11: 1100 | Z11: =SUM(X11*Y11) -> 2123.55
A12: 7 | B12: E04_LOGO_Elec (GRAPHITE ELEC) | C12: COPPER | F12: + | G12: 3 | H12: F | J12: x | L12: x | N12: F0.03/SIDE | O12: BODY INSERT B & P | P12: CNC Milling | Q12: Graphite/Out Source | S12: =I12+5 -> 5 | T12: =K12+5 -> 5 | U12: =M12 -> 0 | V12: =D12+G12 -> 3 | W12: =SUM(S12*T12*U12)*9/1000000 -> 0 | X12: =SUM(V12*W12) -> 0 | Y12: 1100
A14: #RevA Electrodes added on 16-02-2026 by srikanth
A15: PREPARED BY :- Srikanth | C15: Date : 06-11-24 | I15: Date : 16-02-2026 | P15: APPROVED BY :-Srikanth | S15: Total Amount:- | Z15: =SUM(Z6:Z14) -> 14874.42
K23: GRAPHITE
A50: 1 | B50: E01 Groove Elec | C50: COPPER | G50: 1 | H50: F | J50: Æ | K50: 52 | L50: x | M50: 26 | N50: NO GAP | O50: STRIKER INSERT B&P | P50: CNC Turning | S50: =K50+5 -> 57 | T50: =K50+5 -> 57 | V50: =D50+G50 -> 1 | W50: =SUM(3.14*(S50*S50)/4*T50*8/1000000) -> 1.163012 | X50: =SUM(V50*W50) -> 1.163012 | Y50: 1000 | Z50: =SUM(X50*Y50) -> 1163.012

Sheet Partlist- summary
B1: TOOL NO : BM454 Veedol 600ml M01 08Cavity SEB Mold SEB101 FN
A2: S.no | B2: Details | C2: Date | D2: Remarks
A3: 1 | B3: Raw material partlist released | C3: 20-12-2025/Srikanth
A4: 2 | B4: RevA Final sizes,Mold baseparts, Elec,standard parts & Fastners added | C4: 16-02-2026/A.Kalyan

Sheet WQF
A8: 10 | B8: NECK PART B2,P2 | C8: ALUMINIUM | D8: ALUMINIUM | E8: 1 | H8: 740 | I8: x | J8: 55 | K8: x | L8: 3 | N8: 3mm sheet | O8: =H8+5 -> 745 | P8: =J8+5 -> 60 | Q8: =L8+5 -> 8 | R8: =E8+G8 -> 1 | S8: =SUM(O8*P8*Q8)*3/1000000 -> 1.0728 | T8: =SUM(R8*S8) -> 1.0728 | U8: 500 | V8: =SUM(T8*U8) -> 536.4 | W8: 3
A10: 8 | B10: CONNECTING PLATE | C10: ALUMINIUM | D10: 1,2085 | E10: 3 | I10: Ø | J10: 15 | K10: x | L10: 100 | O10: =J10+5 -> 20 | P10: =L10+5 -> 105 | R10: =E10+G10 -> 3 | S10: =SUM(3.14*(O10*O10)/4*P10*W10/1000000) -> 0.26376 | T10: =SUM(R10*S10) -> 0.79128 | U10: 465 | V10: =SUM(T10*U10) -> 367.9452 | W10: 8
D18: 146-31=115
D19: 126-31=95

Sheet SHEET1
A1: WELDURAL | B1: 820 | C1: 3
A2: ALUMOLD1-500 | B2: 952 | C2: 3
A3: HOKOTOL/ALUMOLD1-500 | B3: 952 | C3: 3
A4: HOKOTOL | B4: 952 | C4: 3
A5: ALUMINIUM | B5: 750 | C5: 3
A6: STEEL | B6: 480 | C6: 8 | H6: ALUMINIUM | I6: 750 | J6: 3
A7: D2 | B7: 380 | C7: 8 | H7: STEEL | I7: 480 | J7: 8
A8: 1,2085 | B8: 290 | C8: 8 | H8: FIBER
A9: 1,2085/D2 | B9: 330 | C9: 8
A10: 2316 | B10: 330 | C10: 8
A11: 3,3547 | B11: 750 | C11: 3
A12: 5083 | B12: 750 | C12: 3
A13: 3,4365 | B13: 750 | C13: 3
A14: 3,3206 | B14: 750 | C14: 3
A15: NYLON | B15: 500 | C15: 1.2
A16: ACRYLIC | B16: 500 | C16: 1.2
A17: ABS | B17: 500 | C17: 1.1
A18: BERILIUM COPPER | B18: 5000 | C18: 2
A19: 1,2085/RAMAX | B19: 330 | C19: 8
A20: RAMAX | B20: 310 | C20: 8
A21: K340 | B21: 330 | C21: 8
A22: M315 | B22: 330 | C22: 8
... A27: BRONZE | B27: 650 | C27: 9
